Workbook

Sheet Hoja1
A1: direccion | B1: ciudad | C1: pdv | D1: ean_pdv | E1: Canal
A2: CL.7 # 2-40(B.CENTRO) | B2: EL BANCO | C2: DROGUERIA CENTRAL | D2: 14154 | E2: DROGUERIAS | F2: =VLOOKUP(D2,[1]Hoja3!$A$2:$E$15,5,FALSE) -> #N/A
A3: CR 50 # 22 - 41LOCAL 125 ( SALITRE ORIENTAL ) | B3: BOGOTA | C3: DROGUERIA CIPRESS PLAZA | D3: 14436 | E3: DROGUERIAS | F3: =VLOOKUP(D3,[1]Hoja3!$A$2:$E$15,5,FALSE) -> #N/A
A4: CLL 70A # 90 - 04 ( FLORIDA) | B4: BOGOTA | C4: KOLSUBDROGAS # 2 | D4: 14438 | E4: DROGUERIAS | F4: =VLOOKUP(D4,[1]Hoja3!$A$2:$E$15,5,FALSE) -> #N/A
A5: CR 101 # 72 - 27 (ALAMOS NORTE ) | B5: BOGOTA | C5: CIPRES #1 | D5: 14439 | E5: DROGUERIAS | F5: =VLOOKUP(D5,[1]Hoja3!$A$2:$E$15,5,FALSE) -> #N/A
A6: CR 104 # 64 - 22 ( EL MUELLE) | B6: BOGOTA | C6: DROGUERIA LABTOFAR | D6: 14440 | E6: DROGUERIAS | F6: =VLOOKUP(D6,[1]Hoja3!$A$2:$E$15,5,FALSE) -> #N/A
A7: CL.22 #48-66 (B.PRADOS DEL SALITRE) | B7: BOGOTA | C7: CAUCA # 2 | D7: 14441 | E7: DROGUERIAS | F7: =VLOOKUP(D7,[1]Hoja3!$A$2:$E$15,5,FALSE) -> #N/A
A8: CL.78 # 12-41(B.EL LAGO) | B8: BOGOTA | C8: CENTER LAGOS | D8: 14442 | E8: DROGUERIAS | F8: =VLOOKUP(D8,[1]Hoja3!$A$2:$E$15,5,FALSE) -> #N/A
A9: CR.11 # 92-20 (B.CHICO) | B9: BOGOTA | C9: DISNEY | D9: 14443 | E9: DROGUERIAS | F9: =VLOOKUP(D9,[1]Hoja3!$A$2:$E$15,5,FALSE) -> #N/A
A10: CRA 32A 25A 26 GRAN AMERICA | B10: BOGOTA | C10: DON JERONIMO | D10: 14445 | E10: DROGUERIAS | F10: =VLOOKUP(D10,[1]Hoja3!$A$2:$E$15,5,FALSE) -> #N/A
A11: CR 49 # 99 - 09 ( LA CASTELLANA) | B11: BOGOTA | C11: DROG. DROGAS LA NACIONAL # 4 | D11: 14446 | E11: DROGUERIAS | F11: =VLOOKUP(D11,[1]Hoja3!$A$2:$E$15,5,FALSE) -> #N/A
A12: CLL. 65 # 7 - 80 (QUINTA MACHO) | B12: BOGOTA | C12: DROG. FARMA GRANADA 2 | D12: 14448 | E12: DROGUERIAS | F12: =VLOOKUP(D12,[1]Hoja3!$A$2:$E$15,5,FALSE) -> #N/A
A13: CL.63C # 69P-05(B.BOSQUE POPULAR) | B13: BOGOTA | C13: DROG. M Y M | D13: 14449 | E13: DROGUERIAS | F13: =VLOOKUP(D13,[1]Hoja3!$A$2:$E$15,5,FALSE) -> #N/A
... A4146: CALLE 85 # 50-44 LOCAL 1 | B4146: BARRANQUILLA | C4146: FARMANORTE 39 | D4146: 20139 | E4146: DROGUERIAS | F4146: =VLOOKUP(D4146,[1]Hoja3!$A$2:$E$15,5,FALSE) -> #N/A
B4147: BARRANQUILLA | C4147: FARMANORTE 40 | D4147: 20140 | E4147: DROGUERIAS | F4147: =VLOOKUP(D4147,[1]Hoja3!$A$2:$E$15,5,FALSE) -> #N/A
A4148: CRA 45 CALLE 96 | B4148: BARRANQUILLA | C4148: FARMANORTE 43 | D4148: 20142 | E4148: DROGUERIAS | F4148: =VLOOKUP(D4148,[1]Hoja3!$A$2:$E$15,5,FALSE) -> #N/A
A4149: CALLE 106 N. 50 67 VILLA SANTOS | B4149: BARRANQUILLA | C4149: FARMANORTE 45 | D4149: 20144 | E4149: DROGUERIAS | F4149: =VLOOKUP(D4149,[1]Hoja3!$A$2:$E$15,5,FALSE) -> #N/A
A4150: CL 94 CON 52 | B4150: BARRANQUILLA | C4150: FARMANORTE 46 | D4150: 20145 | E4150: DROGUERIAS | F4150: =VLOOKUP(D4150,[1]Hoja3!$A$2:$E$15,5,FALSE) -> #N/A
A4151: CRA 28 1B-315 BLOQ UM LOCAL 206 CLINICA PORTO AZUL | B4151: BARRANQUILLA | C4151: FARMANORTE 48 | D4151: 20147 | E4151: DROGUERIAS | F4151: =VLOOKUP(D4151,[1]Hoja3!$A$2:$E$15,5,FALSE) -> #N/A
A4152: CALLE 19 # 6A-07 LOCAL 104 BARRIO SIMON BOLIVAR | B4152: BARRANQUILLA | C4152: FARMANORTE 49 | D4152: 20148 | E4152: DROGUERIAS | F4152: =VLOOKUP(D4152,[1]Hoja3!$A$2:$E$15,5,FALSE) -> #N/A
A4153: CARRERA 38 # 70-12 | B4153: BARRANQUILLA | C4153: FARMANORTE 53 | D4153: 20149 | E4153: DROGUERIAS | F4153: =VLOOKUP(D4153,[1]Hoja3!$A$2:$E$15,5,FALSE) -> #N/A
A4154: CALLE 94 CON 52 ESQUINA | B4154: BARRANQUILLA | C4154: FARMANORTE 62 | D4154: 20150 | E4154: DROGUERIAS | F4154: =VLOOKUP(D4154,[1]Hoja3!$A$2:$E$15,5,FALSE) -> #N/A
A4155: CALLE 19# 1D-06 BRR SIMON BOLIVAR | B4155: BARRANQUILLA | C4155: FARMANORTE 77 | D4155: 20154 | E4155: DROGUERIAS | F4155: =VLOOKUP(D4155,[1]Hoja3!$A$2:$E$15,5,FALSE) -> #N/A
B4156: SABANALARGA | C4156: FARMANORTE 79 | D4156: 20155 | E4156: DROGUERIAS | F4156: =VLOOKUP(D4156,[1]Hoja3!$A$2:$E$15,5,FALSE) -> #N/A
A4157: CALLE 71 # 41 - 71 LOCAL 1 | B4157: BARRANQUILLA | C4157: FARMANORTE 91 | D4157: 20156 | E4157: DROGUERIAS | F4157: =VLOOKUP(D4157,[1]Hoja3!$A$2:$E$15,5,FALSE) -> #N/A
A4158: CALLE 27C # 30-02 BRR HIPODROMO | B4158: SOLEDAD | C4158: FARMANORTE 99 | D4158: 20159 | E4158: DROGUERIAS | F4158: =VLOOKUP(D4158,[1]Hoja3!$A$2:$E$15,5,FALSE) -> #N/A
A4159: CLLE 16# 18 -35 | B4159: BARANOA | C4159: FARMAVIDA 72 | D4159: 20164 | E4159: DROGUERIAS | F4159: =VLOOKUP(D4159,[1]Hoja3!$A$2:$E$15,5,FALSE) -> #N/A
A4160: CRA 14B N0 77A -9 VILLA LOS ROBLES | B4160: SOLEDAD | C4160: FARMAVIDA 75 | D4160: 20166 | E4160: DROGUERIAS | F4160: =VLOOKUP(D4160,[1]Hoja3!$A$2:$E$15,5,FALSE) -> #N/A
A4161: KR 48 # 70-115 | B4161: BARRANQUILLA | C4161: FARMAVIDA NO. 04 | D4161: 20170 | E4161: DROGUERIAS | F4161: =VLOOKUP(D4161,[1]Hoja3!$A$2:$E$15,5,FALSE) -> #N/A
A4162: CL 96 # 45B - 58 LC.1 | B4162: BARRANQUILLA | C4162: FARMAVIDA NO. 05 | D4162: 20171 | E4162: DROGUERIAS | F4162: =VLOOKUP(D4162,[1]Hoja3!$A$2:$E$15,5,FALSE) -> #N/A
A4163: KR 49C # 80-13 | B4163: BARRANQUILLA | C4163: FARMAVIDA NO. 06 | D4163: 20172 | E4163: DROGUERIAS | F4163: =VLOOKUP(D4163,[1]Hoja3!$A$2:$E$15,5,FALSE) -> #N/A
A4164: CL 84 # 50-17 LC.1 | B4164: BARRANQUILLA | C4164: FARMAVIDA NO. 08 | D4164: 20173 | E4164: DROGUERIAS | F4164: =VLOOKUP(D4164,[1]Hoja3!$A$2:$E$15,5,FALSE) -> #N/A
A4165: CL 72 # 48-05 ESQUINA | B4165: BARRANQUILLA | C4165: FARMAVIDA NO. 13 | D4165: 20178 | E4165: DROGUERIAS | F4165: =VLOOKUP(D4165,[1]Hoja3!$A$2:$E$15,5,FALSE) -> #N/A
A4166: CL 44 # 8-07 | B4166: BARRANQUILLA | C4166: FARMAVIDA NO. 14 | D4166: 20179 | E4166: DROGUERIAS | F4166: =VLOOKUP(D4166,[1]Hoja3!$A$2:$E$15,5,FALSE) -> #N/A
A4167: KM 7 ANTIGUA VIA PTO. COLOMBIA | B4167: PUERTO COLOMBIA | C4167: FARMAVIDA NO. 17 | D4167: 20182 | E4167: DROGUERIAS | F4167: =VLOOKUP(D4167,[1]Hoja3!$A$2:$E$15,5,FALSE) -> #N/A
A4168: CL 86 # 50-158 LC.3 | B4168: BARRANQUILLA | C4168: FARMAVIDA NO. 25 | D4168: 20188 | E4168: DROGUERIAS | F4168: =VLOOKUP(D4168,[1]Hoja3!$A$2:$E$15,5,FALSE) -> #N/A
... A4192: CALLE 78 NO. 53 - 70 LOCAL 116 CENTRO COMERCIAL VILLA COUNTRY | B4192: BARRANQUILLA | C4192: INGLESA 141 | D4192: 20235 | E4192: DROGUERIAS | F4192: =VLOOKUP(D4192,[1]Hoja3!$A$2:$E$15,5,FALSE) -> #N/A
B4193: BARRANQUILLA | C4193: INGLESA 153 | D4193: 20236 | E4193: DROGUERIAS | F4193: =VLOOKUP(D4193,[1]Hoja3!$A$2:$E$15,5,FALSE) -> #N/A
A4194: CALLE 72 NO. 43 - 7 | B4194: BARRANQUILLA | C4194: INGLESA 172 | D4194: 20237 | E4194: DROGUERIAS | F4194: =VLOOKUP(D4194,[1]Hoja3!$A$2:$E$15,5,FALSE) -> #N/A
A4195: CARRERA 43 NO. 68-13 ESTACIN DE SERVICIO SAN JORGE | B4195: BARRANQUILLA | C4195: INGLESA 191 | D4195: 20238 | E4195: DROGUERIAS | F4195: =VLOOKUP(D4195,[1]Hoja3!$A$2:$E$15,5,FALSE) -> #N/A
...

Sheet Hoja2
A1: direccion | B1: ciudad | C1: pdv | D1: ean_pdv | E1: Canal
A2: CALLE 19 NO. 19-99 | B2: BARANOA | C2: REBAJA PLUS 147 No. 1 BARANOA CENTRO | D2: 7707630000000 | E2: MODERNO | F2: REBAJA PLUS 147 No. 1 BARANOA CENTRO | G2: =VLOOKUP(D2,Hoja1!D:D,1,0) -> #N/A
A3: CALLE 57 NO. 23-47 | B3: BARRANQUILLA | C3: REBAJA PLUS 196 No. 34 BARRANQUILLA LOS ANDES | D3: 7707630000000 | E3: MODERNO | F3: REBAJA PLUS 196 No. 34 BARRANQUILLA LOS ANDES | G3: =VLOOKUP(D3,Hoja1!D:D,1,0) -> #N/A
A4: CARRERA 19 NO. 18-03 ESQUINA | B4: BARANOA | C4: REBAJA PLUS 1N4 No. 2 BARANOA CENTRO | D4: 7707630000000 | E4: MODERNO | F4: REBAJA PLUS 1N4 No. 2 BARANOA CENTRO | G4: =VLOOKUP(D4,Hoja1!D:D,1,0) -> #N/A
A5: KR 9 10 55 BERLIN | B5: PEREIRA | C5: SÚPER BOOM LA 10 | D5: 27329 | E5: TRADICIONAL | F5: SÚPER BOOM LA 10 | G5: =VLOOKUP(D5,Hoja1!D:D,1,0) -> #N/A
A6: KR 8 38 75 CENTRO | B6: PEREIRA | C6: SUPER BOON LA 39 | D6: 27324 | E6: TRADICIONAL | F6: SUPER BOON LA 39 | G6: =VLOOKUP(D6,Hoja1!D:D,1,0) -> #N/A
A7: CL 39 27 12 GALERIA | B7: CALARCA | C7: SUPERMERCADO EL PROGRESO | D7: 27259 | E7: TRADICIONAL | F7: SUPERMERCADO EL PROGRESO | G7: =VLOOKUP(D7,Hoja1!D:D,1,0) -> #N/A
A8: CL 22 14 31 LAURELES | B8: ARMENIA | C8: SUPERMERCADO LAURELES | D8: 27680 | E8: TRADICIONAL | F8: SUPERMERCADO LAURELES | G8: =VLOOKUP(D8,Hoja1!D:D,1,0) -> #N/A
